<sdf version='1.7'>
  <world name='default'>
    <model name='grid_robot'>
      <pose>1.2954 -0.0692 0 0 0 -1.5884</pose>
      <frame name='grid_robot_description::__model__' attached_to='grid_robot_description::base_link'>
        <pose relative_to='__model__'>0 0 0 0 -0 0</pose>
      </frame>
      <link name='grid_robot_description::base_link'>
        <pose relative_to='grid_robot_description::__model__'>0 0 0 0 -0 0</pose>
        <inertial>
          <pose>-0.016778 -0 -0.007997 0 -0 0</pose>
          <mass>0.10648</mass>
          <inertia>
            <ixx>4.9956e-05</ixx>
            <ixy>1.6115e-14</ixy>
            <ixz>-4.2649e-10</ixz>
            <iyy>0.00018031</iyy>
            <iyz>-3.1211e-10</iyz>
            <izz>0.00022562</izz>
          </inertia>
        </inertial>
        <collision name='base_link_collision'>
          <pose>0 0 0 0 -0 0</pose>
          <geometry>
            <mesh>
              <scale>1 1 1</scale>
              <uri>model://grid_robot_description/meshes/base_link.STL</uri>
            </mesh>
          </geometry>
          <max_contacts>10</max_contacts>
          <surface>
            <contact>
              <ode/>
            </contact>
            <bounce/>
            <friction>
              <torsional>
                <ode/>
              </torsional>
              <ode/>
            </friction>
          </surface>
        </collision>
        <visual name='base_link_visual'>
          <pose>0 0 0 0 -0 0</pose>
          <geometry>
            <mesh>
              <scale>1 1 1</scale>
              <uri>model://grid_robot_description/meshes/base_link.STL</uri>
            </mesh>
          </geometry>
          <material>
            <script>
              <name>Gazebo/Grey</name>
              <uri>file://media/materials/scripts/gazebo.material</uri>
            </script>
          </material>
        </visual>
        <visual name='april_tag_visual'>
          <pose>0 0 0.001 0 -0 0</pose>
          <geometry>
            <plane>
              <normal>0 0 1</normal>
              <size>0.1 0.1</size>
            </plane>
          </geometry>
          <material>
            <script>
              <uri>model://grid_robot_description/materials/scripts</uri>
              <uri>model://grid_robot_description/materials/textures</uri>
              <name>april_tag/Image</name>
            </script>
          </material>
        </visual>
        <self_collide>0</self_collide>
        <enable_wind>0</enable_wind>
        <kinematic>0</kinematic>
      </link>
      <link name='grid_robot_description::left_wheel_link'>
        <pose relative_to='grid_robot_description::__model__'>0.00725 0.0755 -0.013684 0 -0 0</pose>
        <inertial>
          <pose>-0 -0.011873 -0 0 -0 0</pose>
          <mass>0.16695</mass>
          <inertia>
            <ixx>6.7294e-05</ixx>
            <ixy>1.8343e-12</ixy>
            <ixz>1.6475e-09</ixz>
            <iyy>0.00011321</iyy>
            <iyz>2.6313e-12</iyz>
            <izz>6.7295e-05</izz>
          </inertia>
        </inertial>
        <collision name='left_wheel_link_collision'>
          <pose>0 0 0 0 -0 0</pose>
          <geometry>
            <mesh>
              <scale>1 1 1</scale>
              <uri>model://grid_robot_description/meshes/left_wheel_link.STL</uri>
            </mesh>
          </geometry>
          <max_contacts>10</max_contacts>
          <surface>
            <contact>
              <ode/>
            </contact>
            <bounce/>
            <friction>
              <torsional>
                <ode/>
              </torsional>
              <ode/>
            </friction>
          </surface>
        </collision>
        <visual name='left_wheel_link_visual'>
          <pose>0 0 0 0 -0 0</pose>
          <geometry>
            <mesh>
              <scale>1 1 1</scale>
              <uri>model://grid_robot_description/meshes/left_wheel_link.STL</uri>
            </mesh>
          </geometry>
          <material>
            <script>
              <name>Gazebo/DarkGrey</name>
              <uri>file://media/materials/scripts/gazebo.material</uri>
            </script>
          </material>
        </visual>
        <self_collide>0</self_collide>
        <enable_wind>0</enable_wind>
        <kinematic>0</kinematic>
      </link>
      <joint name='grid_robot_description::left_wheel_joint' type='revolute'>
        <child>grid_robot_description::left_wheel_link</child>
        <parent>grid_robot_description::base_link</parent>
        <axis>
          <xyz expressed_in='grid_robot_description::__model__'>0 1 0</xyz>
          <limit>
            <lower>-1e+16</lower>
            <upper>1e+16</upper>
          </limit>
          <dynamics>
            <spring_reference>0</spring_reference>
            <spring_stiffness>0</spring_stiffness>
          </dynamics>
        </axis>
      </joint>
      <link name='grid_robot_description::right_wheel_link'>
        <pose relative_to='grid_robot_description::__model__'>0.00725 -0.0755 -0.013816 0 -0 0</pose>
        <inertial>
          <pose>0 0.011873 0 0 -0 0</pose>
          <mass>0.16695</mass>
          <inertia>
            <ixx>6.7294e-05</ixx>
            <ixy>1.7315e-12</ixy>
            <ixz>1.7871e-09</ixz>
            <iyy>0.00011321</iyy>
            <iyz>2.7e-12</iyz>
            <izz>6.7295e-05</izz>
          </inertia>
        </inertial>
        <collision name='right_wheel_link_collision'>
          <pose>0 0 0 0 -0 0</pose>
          <geometry>
            <mesh>
              <scale>1 1 1</scale>
              <uri>model://grid_robot_description/meshes/right_wheel_link.STL</uri>
            </mesh>
          </geometry>
          <max_contacts>10</max_contacts>
          <surface>
            <contact>
              <ode/>
            </contact>
            <bounce/>
            <friction>
              <torsional>
                <ode/>
              </torsional>
              <ode/>
            </friction>
          </surface>
        </collision>
        <visual name='right_wheel_link_visual'>
          <pose>0 0 0 0 -0 0</pose>
          <geometry>
            <mesh>
              <scale>1 1 1</scale>
              <uri>model://grid_robot_description/meshes/right_wheel_link.STL</uri>
            </mesh>
          </geometry>
          <material>
            <script>
              <name>Gazebo/DarkGrey</name>
              <uri>file://media/materials/scripts/gazebo.material</uri>
            </script>
          </material>
        </visual>
        <self_collide>0</self_collide>
        <enable_wind>0</enable_wind>
        <kinematic>0</kinematic>
      </link>
      <joint name='grid_robot_description::right_wheel_joint' type='revolute'>
        <child>grid_robot_description::right_wheel_link</child>
        <parent>grid_robot_description::base_link</parent>
        <axis>
          <xyz expressed_in='grid_robot_description::__model__'>0 1 0</xyz>
          <limit>
            <lower>-1e+16</lower>
            <upper>1e+16</upper>
          </limit>
          <dynamics>
            <spring_reference>0</spring_reference>
            <spring_stiffness>0</spring_stiffness>
          </dynamics>
        </axis>
      </joint>
      <plugin name='differential_drive_controller' filename='libgazebo_ros_diff_drive.so'>
        <updateRate>100</updateRate>
        <leftJoint>grid_robot_description::left_wheel_joint</leftJoint>
        <rightJoint>grid_robot_description::right_wheel_joint</rightJoint>
        <wheelSeparation>0.151</wheelSeparation>
        <wheelDiameter>0.06918</wheelDiameter>
        <wheelAcceleration>1.0</wheelAcceleration>
        <wheelTorque>5</wheelTorque>
        <commandTopic>cmd_vel</commandTopic>
        <odometryTopic>odom</odometryTopic>
        <odometryFrame>odom</odometryFrame>
        <robotBaseFrame>base_footprint</robotBaseFrame>
        <odometrySource>1</odometrySource>
        <publishWheelTF>1</publishWheelTF>
        <publishOdom>1</publishOdom>
        <publishWheelJointState>1</publishWheelJointState>
        <legacyMode>0</legacyMode>
      </plugin>
    </model>
    <light name='sun' type='directional'>
      <cast_shadows>1</cast_shadows>
      <pose>0 0 10 0 -0 0</pose>
      <diffuse>0.8 0.8 0.8 1</diffuse>
      <specular>0.2 0.2 0.2 1</specular>
      <attenuation>
        <range>1000</range>
        <constant>0.9</constant>
        <linear>0.01</linear>
        <quadratic>0.001</quadratic>
      </attenuation>
      <direction>-0.5 0.1 -0.9</direction>
      <spot>
        <inner_angle>0</inner_angle>
        <outer_angle>0</outer_angle>
        <falloff>0</falloff>
      </spot>
    </light>
    <model name='ground_plane'>
      <static>1</static>
      <link name='link'>
        <collision name='collision'>
          <geometry>
            <plane>
              <normal>0 0 1</normal>
              <size>100 100</size>
            </plane>
          </geometry>
          <surface>
            <contact>
              <collide_bitmask>65535</collide_bitmask>
              <ode/>
            </contact>
            <friction>
              <ode>
                <mu>100</mu>
                <mu2>50</mu2>
              </ode>
              <torsional>
                <ode/>
              </torsional>
            </friction>
            <bounce/>
          </surface>
          <max_contacts>10</max_contacts>
        </collision>
        <visual name='visual'>
          <cast_shadows>0</cast_shadows>
          <geometry>
            <plane>
              <normal>0 0 1</normal>
              <size>100 100</size>
            </plane>
          </geometry>
          <material>
            <script>
              <uri>file://media/materials/scripts/gazebo.material</uri>
              <name>Gazebo/Grey</name>
            </script>
          </material>
        </visual>
        <self_collide>0</self_collide>
        <enable_wind>0</enable_wind>
        <kinematic>0</kinematic>
      </link>
    </model>
    <gravity>0 0 -9.8</gravity>
    <magnetic_field>6e-06 2.3e-05 -4.2e-05</magnetic_field>
    <atmosphere type='adiabatic'/>
    <physics type='ode'>
      <max_step_size>0.001</max_step_size>
      <real_time_factor>1</real_time_factor>
      <real_time_update_rate>1000</real_time_update_rate>
    </physics>
    <scene>
      <ambient>0.4 0.4 0.4 1</ambient>
      <background>0.7 0.7 0.7 1</background>
      <shadows>1</shadows>
    </scene>
    <wind/>
    <spherical_coordinates>
      <surface_model>EARTH_WGS84</surface_model>
      <latitude_deg>0</latitude_deg>
      <longitude_deg>0</longitude_deg>
      <elevation>0</elevation>
      <heading_deg>0</heading_deg>
    </spherical_coordinates>
    <state world_name='default'>
      <sim_time>73 297000000</sim_time>
      <real_time>35 411799598</real_time>
      <wall_time>1661135963 47867532</wall_time>
      <iterations>30853</iterations>
      <model name='grid_robot'>
        <pose>1.2952 -0.083707 0.048089 -0.001098 -0.015826 -1.56526</pose>
        <scale>1 1 1</scale>
        <link name='grid_robot_description::base_link'>
          <pose>1.2952 -0.083707 0.048089 -0.001098 -0.015826 -1.56526</pose>
          <velocity>0.000929 -0.000979 -0.001682 0.016801 0.023832 -0.001563</velocity>
          <acceleration>2.2662 0.329221 -5.03744 1.87285 -0.530938 0.68043</acceleration>
          <wrench>0.241305 0.035056 -0.536387 0 -0 0</wrench>
        </link>
        <link name='grid_robot_description::left_wheel_link'>
          <pose>1.37073 -0.090756 0.034439 -0.001113 -0.019137 -1.56526</pose>
          <velocity>0.000649 -0.000854 -0.003758 0.01709 0.019947 -0.001333</velocity>
          <acceleration>1.95338 0.153842 -9.30763 2.21449 -0.170871 1.36079</acceleration>
          <wrench>0.326116 0.025684 -1.55391 0 -0 0</wrench>
        </link>
        <link name='grid_robot_description::right_wheel_link'>
          <pose>1.21973 -0.091591 0.034472 -0.001059 0.155538 -1.56544</pose>
          <velocity>0.000659 -0.000618 0.000198 0.018378 0.019375 -0.001544</velocity>
          <acceleration>1.96617 0.403418 -0.073861 2.19074 0.942318 1.01309</acceleration>
          <wrench>0.328252 0.067351 -0.012331 0 -0 0</wrench>
        </link>
      </model>
      <model name='ground_plane'>
        <pose>0 0 0 0 -0 0</pose>
        <scale>1 1 1</scale>
        <link name='link'>
          <pose>0 0 0 0 -0 0</pose>
          <velocity>0 0 0 0 -0 0</velocity>
          <acceleration>0 0 0 0 -0 0</acceleration>
          <wrench>0 0 0 0 -0 0</wrench>
        </link>
      </model>
      <light name='sun'>
        <pose>0 0 10 0 -0 0</pose>
      </light>
    </state>
    <gui fullscreen='0'>
      <camera name='user_camera'>
        <pose>5.86916 -4.31349 2.10364 0 0.275643 2.35619</pose>
        <view_controller>orbit</view_controller>
        <projection_type>perspective</projection_type>
      </camera>
    </gui>
  </world>
</sdf>
